<?xml version="1.0"?>
<robot name="LW">
  <link name="base_link">
    <inertial>
      <origin
        xyz="0.09363836 0.00071974 -0.03341964"
        rpy="0 0 0" />
      <mass
        value="10.76493269" />
      <inertia
        ixx="0.11868246"
        ixy="-0.00008927"
        ixz="-0.01324409"
        iyy="0.10939137"
        iyz="0.00056877"
        izz="0.10398242" />
    </inertial>
    <visual>
      <origin xyz="0.000000 0.000000 0.000000" rpy="0.000000 0.000000 0.000000"/>
      <geometry>
        <mesh filename="meshes/base_link.stl"/>
      </geometry>
    </visual>
    <collision>
      <origin xyz="0.000000 0.000000 0.000000" rpy="0.000000 0.000000 0.000000"/>
      <geometry>
        <mesh filename="meshes/base_link.stl"/>
      </geometry>
    </collision>
  </link>
  <link name="right_hip_link">
    <inertial>
      <origin
        xyz="0.01209628 0.00236360 0.00082575"
        rpy="0 0 0" />
      <mass
        value="1.69532239" />
      <inertia
        ixx="0.00160090"
        ixy="0.00027900"
        ixz="0.00003060"
        iyy="0.00300536"
        iyz="0.00000703"
        izz="0.00266370" />
    </inertial>
    <visual>
      <origin xyz="0.000000 0.000000 0.000000" rpy="0.000000 0.000000 0.000000"/>
      <geometry>
        <mesh filename="meshes/right_hip.stl"/>
      </geometry>
    </visual>
    <collision>
      <origin xyz="0.000000 0.000000 0.000000" rpy="0.000000 0.000000 0.000000"/>
      <geometry>
        <mesh filename="meshes/right_hip.stl"/>
      </geometry>
    </collision>
  </link>
  <link name="right_thigh_link">
    <inertial>
      <origin
        xyz="0.00184534 0.01711708 -0.19844668"
        rpy="0 0 0" />
      <mass
        value="2.08292210" />
      <inertia
        ixx="0.02381800"
        ixy="0.00002197"
        ixz="0.00025062"
        iyy="0.02487270"
        iyz="0.00095727"
        izz="0.00222419" />
    </inertial>
    <visual>
      <origin xyz="0.000000 0.000000 0.000000" rpy="0.000000 0.000000 0.000000"/>
      <geometry>
        <mesh filename="meshes/right_thigh.stl"/>
      </geometry>
    </visual>
    <collision>
      <origin xyz="0.000000 0.000000 0.000000" rpy="0.000000 0.000000 0.000000"/>
      <geometry>
        <mesh filename="meshes/right_thigh.stl"/>
      </geometry>
    </collision>
  </link>
  <link name="right_shank_link">
    <inertial>
      <origin
        xyz="-0.10137469 -0.01753330 -0.02485088"
        rpy="0 0 0" />
      <mass
        value="1.97447981" />
      <inertia
        ixx="0.07867343"
        ixy="-0.00127684"
        ixz="-0.03069711"
        iyy="0.09441814"
        iyz="-0.00168612"
        izz="0.01693077" />
    </inertial>
    <visual>
      <origin xyz="0.000000 0.000000 0.000000" rpy="0.000000 0.000000 0.000000"/>
      <geometry>
        <mesh filename="meshes/right_shank.stl"/>
      </geometry>
    </visual>
    <collision>
      <origin xyz="0.000000 0.000000 0.000000" rpy="0.000000 0.000000 0.000000"/>
      <geometry>
        <mesh filename="meshes/right_shank.stl"/>
      </geometry>
    </collision>
  </link>
  <link name="right_wheel_link">
    <inertial>
      <origin
        xyz="0.0 -0.00593046 0.0"
        rpy="0 0 0" />
      <mass
        value="1.18607212" />
      <inertia
        ixx="0.00406726"
        ixy="0.0"
        ixz="0.0"
        iyy="0.00771907"
        iyz="0.0"
        izz="0.00406726" />
    </inertial>
    <visual>
      <origin xyz="0.000000 0.000000 0.000000" rpy="0.000000 0.000000 0.000000"/>
      <geometry>
        <mesh filename="meshes/right_wheel.stl"/>
      </geometry>
    </visual>
    <collision>
      <origin xyz="0.000000 0.000000 0.000000" rpy="0.000000 0.000000 0.000000"/>
      <geometry>
        <mesh filename="meshes/right_wheel.stl"/>
      </geometry>
    </collision>
  </link>
  <link name="right_foot_link">
    <inertial>
      <origin
        xyz="0.0 -0.00054044 0.05031524"
        rpy="0 0 0" />
      <mass
        value="0.39895837" />
      <inertia
        ixx="0.00036067"
        ixy="0.0"
        ixz="0.0"
        iyy="0.00101680"
        iyz="-0.00000084"
        izz="0.00120664" />
    </inertial>
    <visual>
      <origin xyz="0.000000 0.000000 0.000000" rpy="0.000000 0.000000 0.000000"/>
      <geometry>
        <mesh filename="meshes/right_foot.stl"/>
      </geometry>
    </visual>
    <collision>
      <origin xyz="0.000000 0.000000 0.000000" rpy="0.000000 0.000000 0.000000"/>
      <geometry>
        <mesh filename="meshes/right_foot.stl"/>
      </geometry>
    </collision>
  </link>
  <link name="left_hip_link">
    <inertial>
      <origin
        xyz="0.00755272 -0.00236360 0.00082575"
        rpy="0 0 0" />
      <mass
        value="1.69532239" />
      <inertia
        ixx="0.00160090"
        ixy="-0.00023280"
        ixz="-0.00000309"
        iyy="0.00315671"
        iyz="-0.00000703"
        izz="0.00281505" />
    </inertial>
    <visual>
      <origin xyz="0.000000 0.000000 0.000000" rpy="0.000000 0.000000 0.000000"/>
      <geometry>
        <mesh filename="meshes/left_hip.stl"/>
      </geometry>
    </visual>
    <collision>
      <origin xyz="0.000000 0.000000 0.000000" rpy="0.000000 0.000000 0.000000"/>
      <geometry>
        <mesh filename="meshes/left_hip.stl"/>
      </geometry>
    </collision>
  </link>
  <link name="left_thigh_link">
    <inertial>
      <origin
        xyz="-0.00185274 -0.01711716 -0.19844796"
        rpy="0 0 0" />
      <mass
        value="2.08290871" />
      <inertia
        ixx="0.02381747"
        ixy="0.00002233"
        ixz="-0.00025084"
        iyy="0.02487208"
        iyz="-0.00095724"
        izz="0.00222409" />
    </inertial>
    <visual>
      <origin xyz="0.000000 0.000000 0.000000" rpy="0.000000 0.000000 0.000000"/>
      <geometry>
        <mesh filename="meshes/left_thigh.stl"/>
      </geometry>
    </visual>
    <collision>
      <origin xyz="0.000000 0.000000 0.000000" rpy="0.000000 0.000000 0.000000"/>
      <geometry>
        <mesh filename="meshes/left_thigh.stl"/>
      </geometry>
    </collision>
  </link>
  <link name="left_shank_link">
    <inertial>
      <origin
        xyz="-0.10139902 0.01753330 -0.02482657"
        rpy="0 0 0" />
      <mass
        value="1.97447981" />
      <inertia
        ixx="0.07865791"
        ixy="0.00127577"
        ixz="-0.03070076"
        iyy="0.09441078"
        iyz="0.00168719"
        izz="0.01693893" />
    </inertial>
    <visual>
      <origin xyz="0.000000 0.000000 0.000000" rpy="0.000000 0.000000 0.000000"/>
      <geometry>
        <mesh filename="meshes/left_shank.stl"/>
      </geometry>
    </visual>
    <collision>
      <origin xyz="0.000000 0.000000 0.000000" rpy="0.000000 0.000000 0.000000"/>
      <geometry>
        <mesh filename="meshes/left_shank.stl"/>
      </geometry>
    </collision>
  </link>
  <link name="left_wheel_link">
    <inertial>
      <origin
        xyz="0.0 0.00443046 0.0"
        rpy="0 0 0" />
      <mass
        value="1.18607212" />
      <inertia
        ixx="0.00406726"
        ixy="0.0"
        ixz="0.0"
        iyy="0.00771907"
        iyz="0.0"
        izz="0.00406726" />
    </inertial>
    <visual>
      <origin xyz="0.000000 0.000000 0.000000" rpy="0.000000 0.000000 0.000000"/>
      <geometry>
        <mesh filename="meshes/left_wheel.stl"/>
      </geometry>
    </visual>
    <collision>
      <origin xyz="0.000000 0.000000 0.000000" rpy="0.000000 0.000000 0.000000"/>
      <geometry>
        <mesh filename="meshes/left_wheel.stl"/>
      </geometry>
    </collision>
  </link>
  <link name="left_foot_link">
    <inertial>
      <origin
        xyz="0.0 0.00054044 0.05031524"
        rpy="0 0 0" />
      <mass
        value="0.39895837" />
      <inertia
        ixx="0.00036067"
        ixy="0.0"
        ixz="0.0"
        iyy="0.00101680"
        iyz="0.00000084"
        izz="0.00120664" />
    </inertial>
    <visual>
      <origin xyz="0.000000 0.000000 0.000000" rpy="0.000000 0.000000 0.000000"/>
      <geometry>
        <mesh filename="meshes/left_foot.stl"/>
      </geometry>
    </visual>
    <collision>
      <origin xyz="0.000000 0.000000 0.000000" rpy="0.000000 0.000000 0.000000"/>
      <geometry>
        <mesh filename="meshes/left_foot.stl"/>
      </geometry>
    </collision>
  </link>

  <joint name="right_hip_joint" type="revolute">
    <parent link="base_link"/>
    <child link="right_hip_link"/>
    <origin xyz="-0.077000 -0.080000 -0.115700" rpy="0.000000 -0.000000 0.000000"/>
    <axis xyz="-1.000000 0.000000 0.000000"/>
    <limit lower="-1.570796" upper="1.570796" effort="120.000000" velocity="20.000000"/>
  </joint>
  <joint name="left_hip_joint" type="revolute">
    <parent link="base_link"/>
    <child link="left_hip_link"/>
    <origin xyz="-0.077000 0.080000 -0.115700" rpy="0.000000 -0.000000 0.000000"/>
    <axis xyz="-1.000000 0.000000 0.000000"/>
    <limit lower="-1.570796" upper="1.570796" effort="120.000000" velocity="20.000000"/>
  </joint>
  <joint name="right_thigh_joint" type="revolute">
    <parent link="right_hip_link"/>
    <child link="right_thigh_link"/>
    <origin xyz="0.000000 -0.072000 0.000000" rpy="0.000000 -0.000000 0.000000"/>
    <axis xyz="0.000000 -1.000000 0.000000"/>
    <limit lower="-1.570796" upper="1.570796" effort="120.000000" velocity="20.000000"/>
  </joint>
  <joint name="left_thigh_joint" type="revolute">
    <parent link="left_hip_link"/>
    <child link="left_thigh_link"/>
    <origin xyz="0.000000 0.072000 0.000000" rpy="0.000000 -0.000000 0.000000"/>
    <axis xyz="0.000000 1.000000 0.000000"/>
    <limit lower="-1.570796" upper="1.570796" effort="120.000000" velocity="20.000000"/>
  </joint>
  <joint name="right_shank_joint" type="revolute">
    <parent link="right_thigh_link"/>
    <child link="right_shank_link"/>
    <origin xyz="0.000000 -0.045000 -0.260000" rpy="0.000000 -0.000000 0.000000"/>
    <axis xyz="0.000000 -1.000000 0.000000"/>
    <limit lower="-3.141593" upper="3.141593" effort="120.000000" velocity="20.000000"/>
  </joint>
  <joint name="left_shank_joint" type="revolute">
    <parent link="left_thigh_link"/>
    <child link="left_shank_link"/>
    <origin xyz="0.000000 0.045000 -0.260000" rpy="0.000000 -0.000000 0.000000"/>
    <axis xyz="0.000000 1.000000 0.000000"/>
    <limit lower="-3.141593" upper="3.141593" effort="120.000000" velocity="20.000000"/>
  </joint>
  <joint name="right_wheel_joint" type="continuous">
    <parent link="right_shank_link"/>
    <child link="right_wheel_link"/>
    <origin xyz="-0.183850 -0.059500 -0.183850" rpy="0.000000 -0.000000 0.000000"/>
    <axis xyz="0.000000 -1.000000 0.000000"/>
    <limit effort="40.000000" velocity="33.000000"/>
  </joint>
  <joint name="left_wheel_joint" type="continuous">
    <parent link="left_shank_link"/>
    <child link="left_wheel_link"/>
    <origin xyz="-0.183850 0.061000 -0.183850" rpy="0.000000 -0.000000 0.000000"/>
    <axis xyz="0.000000 1.000000 0.000000"/>
    <limit effort="40.000000" velocity="33.000000"/>
  </joint>
  <joint name="right_foot_joint" type="revolute">
    <parent link="right_shank_link"/>
    <child link="right_foot_link"/>
    <origin xyz="0.000000 -0.013000 0.307000" rpy="0.000000 -0.000000 0.000000"/>
    <axis xyz="0.000000 -1.000000 0.000000"/>
    <limit lower="-1.919862" upper="1.919862" effort="27.000000" velocity="10.000000"/>
  </joint>
  <joint name="left_foot_joint" type="revolute">
    <parent link="left_shank_link"/>
    <child link="left_foot_link"/>
    <origin xyz="0.000000 0.013000 0.307000" rpy="0.000000 -0.000000 0.000000"/>
    <axis xyz="0.000000 1.000000 0.000000"/>
    <limit lower="-1.919862" upper="1.919862" effort="27.000000" velocity="10.000000"/>
  </joint>
</robot>
